Workbook

Sheet Carta Gantt
A1: CARTA GANTT 60 DÍAS CORRIDOS — PROYECTO DOÑA CARNE MANQUEHUE 1 (cuadrillas consolidadas por especialidad)
A2: Una misma cuadrilla por especialidad ejecuta varios ítems chicos en secuencia (no una cuadrilla dedicada por ítem). Ver hoja 'Resumen Cuadrillas' y 'Chequeo vs Presupuesto'.
A3: Cuadrilla / Especialidad | B3: Sección | C3: N° | D3: Partida | E3: Unidad | F3: Cantidad | G3: Rendimiento (u/día x cuadrilla) | H3: Cuadrilla-días necesarios | I3: Ventana Día Ini | J3: Ventana Día Fin | K3: 1 | L3: 2 | M3: 3 | N3: 4 | O3: 5 | P3: 6 | Q3: 7 | R3: 8 | S3: 9 | T3: 10 | U3: 11 | V3: 12 | W3: 13 | X3: 14 | Y3: 15 | Z3: 16 | AA3: 17 | AB3: 18 | AC3: 19 | AD3: 20 | AE3: 21 | AF3: 22 | AG3: 23 | AH3: 24 | AI3: 25 | AJ3: 26 | AK3: 27 | AL3: 28 | AM3: 29 | AN3: 30 | AO3: 31 | AP3: 32 | AQ3: 33 | AR3: 34 | AS3: 35 | AT3: 36 | AU3: 37 | AV3: 38 | AW3: 39 | AX3: 40 | AY3: 41 | AZ3: 42 | BA3: 43 | BB3: 44 | BC3: 45 | BD3: 46 | BE3: 47 | BF3: 48 | BG3: 49 | BH3: 50 | BI3: 51 | BJ3: 52 | BK3: 53 | BL3: 54 | BM3: 55 | BN3: 56 | BO3: 57 | BP3: 58 | BQ3: 59 | BR3: 60
A4: T1. Demolición y Retiros | B4: A. DEMOLICIONES Y RETIROS | C4: 1 | D4: Retiro de piso flotante existente 1er Nivel | E4: m2 | F4: 301 | G4: 35 | H4: =F4/G4 -> 8.6 | I4: 1 | J4: 10
A5: T1. Demolición y Retiros | B5: A. DEMOLICIONES Y RETIROS | C5: 2 | D5: Retiro de piso flotante existente 2do nivel | E5: m2 | F5: 49 | G5: 35 | H5: =F5/G5 -> 1.4 | I5: 1 | J5: 10
A6: T1. Demolición y Retiros | B6: A. DEMOLICIONES Y RETIROS | C6: 5 | D6: Retiro de cielo americano existente 1er Piso | E6: m2 | F6: 137 | G6: 40 | H6: =F6/G6 -> 3.425 | I6: 1 | J6: 10
A7: T1. Demolición y Retiros | B7: A. DEMOLICIONES Y RETIROS | C7: 6 | D7: Retiro de cielo americano existente 2do Piso | E7: m2 | F7: 49 | G7: 40 | H7: =F7/G7 -> 1.225 | I7: 1 | J7: 10
A8: T2. Obra Gruesa / Hormigones | B8: A. DEMOLICIONES Y RETIROS | C8: 3 | D8: Rotura de pavimento para paso de alcantarillado | E8: m2 | F8: 36 | G8: 6 | H8: =F8/G8 -> 6 | I8: 1 | J8: 13
A9: T2. Obra Gruesa / Hormigones | B9: A. DEMOLICIONES Y RETIROS | C9: 4 | D9: Reposición de pavimento para paso de alcantarillado | E9: m2 | F9: 36 | G9: 15 | H9: =F9/G9 -> 2.4 | I9: 1 | J9: 13
A10: T2. Obra Gruesa / Hormigones | B10: A. DEMOLICIONES Y RETIROS | C10: 8 | D10: Rotura piso hormigón Sala congelados H=0,6m | E10: m3 | F10: 18 | G10: 3 | H10: =F10/G10 -> 6 | I10: 1 | J10: 13
A11: T2. Obra Gruesa / Hormigones | B11: A. DEMOLICIONES Y RETIROS | C11: 9 | D11: Hormigón piso sala de congelados e=100mm | E11: m2 | F11: 7 | G11: 12 | H11: =F11/G11 -> 0.58333333 | I11: 1 | J11: 13
A12: T2. Obra Gruesa / Hormigones | B12: A. DEMOLICIONES Y RETIROS | C12: 11 | D12: Barrera de vapor | E12: m2 | F12: 18 | G12: 200 | H12: =F12/G12 -> 0.09 | I12: 1 | J12: 13
A13: T2. Obra Gruesa / Hormigones | B13: A. DEMOLICIONES Y RETIROS | C13: 12 | D13: Panel de piso Isopur bajo losa e=150mm | E13: m2 | F13: 18 | G13: 25 | H13: =F13/G13 -> 0.72 | I13: 1 | J13: 13
A14: T2. Obra Gruesa / Hormigones | B14: A. DEMOLICIONES Y RETIROS | C14: 13 | D14: Hormigón Subsuelo base cámara de frío | E14: m2 | F14: 18 | G14: 12 | H14: =F14/G14 -> 1.5 | I14: 1 | J14: 13
A15: T2. Obra Gruesa / Hormigones | B15: A. DEMOLICIONES Y RETIROS | C15: 16 | D15: Radier afinado área residuos y bodega PR2 | E15: m2 | F15: 12 | G15: 20 | H15: =F15/G15 -> 0.6 | I15: 1 | J15: 13
... A54: T13. Limpieza / Retiro escombros | B54: G. HOJALATERÍA Y CUBIERTA | C54: 6 | D54: Retiro de escombros (continuo) | E54: gl | F54: 1 | G54: 1 | H54: =F54/G54 -> 1 | I54: 1 | J54: 60

Sheet Resumen Cuadrillas
A1: RESUMEN DE CUADRILLAS CONSOLIDADAS POR ESPECIALIDAD
A3: Cuadrilla / Especialidad | B3: Cuadrilla-días totales (suma ítems) | C3: Ventana Día Ini | D3: Ventana Día Fin | E3: Días ventana | F3: Cuadrillas necesarias | G3: Personas x cuadrilla | H3: Dotación total (pers.) | I3: Duración real (días)
A4: T1. Demolición y Retiros | B4: ='Carta Gantt'!H4+'Carta Gantt'!H5+'Carta Gantt'!H6+'Carta Gantt'!H7 -> 14.65 | C4: 1 | D4: 10 | E4: =D4-C4+1 -> 10 | F4: =CEILING(B4/E4,1) -> 2 | G4: 2 | H4: =F4*G4 -> 4 | I4: =CEILING(B4/F4,1) -> 8
A5: T2. Obra Gruesa / Hormigones | B5: ='Carta Gantt'!H8+'Carta Gantt'!H9+'Carta Gantt'!H10+'Carta Gantt'!H11+'Carta Gantt'!H12+'Carta Gantt'!H13+'Carta Gantt'!H14+'Carta Gantt'!H15 -> 17.893333 | C5: 1 | D5: 13 | E5: =D5-C5+1 -> 13 | F5: =CEILING(B5/E5,1) -> 2 | G5: 2 | H5: =F5*G5 -> 4 | I5: =CEILING(B5/F5,1) -> 9
A6: T3. Enfierradura | B6: ='Carta Gantt'!H16 -> 1.8 | C6: 6 | D6: 11 | E6: =D6-C6+1 -> 6 | F6: =CEILING(B6/E6,1) -> 1 | G6: 2 | H6: =F6*G6 -> 2 | I6: =CEILING(B6/F6,1) -> 2
A7: T4. Zócalos y Ángulos | B7: ='Carta Gantt'!H17+'Carta Gantt'!H18 -> 26.6 | C7: 4 | D7: 20 | E7: =D7-C7+1 -> 17 | F7: =CEILING(B7/E7,1) -> 2 | G7: 2 | H7: =F7*G7 -> 4 | I7: =CEILING(B7/F7,1) -> 14
A8: T5. Tabiquería / Drywall | B8: ='Carta Gantt'!H19+'Carta Gantt'!H20+'Carta Gantt'!H21+'Carta Gantt'!H22+'Carta Gantt'!H23+'Carta Gantt'!H24+'Carta Gantt'!H25 -> 33.044444 | C8: 12 | D8: 26 | E8: =D8-C8+1 -> 15 | F8: =CEILING(B8/E8,1) -> 3 | G8: 2 | H8: =F8*G8 -> 6 | I8: =CEILING(B8/F8,1) -> 12
A9: T6. Estructura Metálica | B9: ='Carta Gantt'!H26+'Carta Gantt'!H27 -> 3.1666667 | C9: 12 | D9: 22 | E9: =D9-C9+1 -> 11 | F9: =CEILING(B9/E9,1) -> 1 | G9: 3 | H9: =F9*G9 -> 3 | I9: =CEILING(B9/F9,1) -> 4
A10: T7. Paneles Frigoríficos | B10: ='Carta Gantt'!H28+'Carta Gantt'!H29+'Carta Gantt'!H30+'Carta Gantt'!H31 -> 24.404545 | C10: 20 | D10: 34 | E10: =D10-C10+1 -> 15 | F10: =CEILING(B10/E10,1) -> 2 | G10: 2 | H10: =F10*G10 -> 4 | I10: =CEILING(B10/F10,1) -> 13
A11: T8. Cielos | B11: ='Carta Gantt'!H32+'Carta Gantt'!H33+'Carta Gantt'!H34+'Carta Gantt'!H35+'Carta Gantt'!H36+'Carta Gantt'!H37+'Carta Gantt'!H38 -> 15.207071 | C11: 26 | D11: 40 | E11: =D11-C11+1 -> 15 | F11: =CEILING(B11/E11,1) -> 2 | G11: 2 | H11: =F11*G11 -> 4 | I11: =CEILING(B11/F11,1) -> 8
A12: T9. Pisos / Cerámicos | B12: ='Carta Gantt'!H39+'Carta Gantt'!H40+'Carta Gantt'!H41+'Carta Gantt'!H42+'Carta Gantt'!H43 -> 45.616667 | C12: 38 | D12: 52 | E12: =D12-C12+1 -> 15 | F12: =CEILING(B12/E12,1) -> 4 | G12: 2 | H12: =F12*G12 -> 8 | I12: =CEILING(B12/F12,1) -> 12
A13: T10a. Pintura Estructura | B13: ='Carta Gantt'!H44+'Carta Gantt'!H45+'Carta Gantt'!H46 -> 4.1333333 | C13: 18 | D13: 28 | E13: =D13-C13+1 -> 11 | F13: =CEILING(B13/E13,1) -> 1 | G13: 2 | H13: =F13*G13 -> 2 | I13: =CEILING(B13/F13,1) -> 5
A14: T10b. Pintura Interior | B14: ='Carta Gantt'!H47 -> 10.625 | C14: 34 | D14: 52 | E14: =D14-C14+1 -> 19 | F14: =CEILING(B14/E14,1) -> 1 | G14: 2 | H14: =F14*G14 -> 2 | I14: =CEILING(B14/F14,1) -> 11
A15: T11. Hojalatería / Cubierta | B15: ='Carta Gantt'!H48+'Carta Gantt'!H49+'Carta Gantt'!H50+'Carta Gantt'!H51+'Carta Gantt'!H52 -> 77.091667 | C15: 3 | D15: 30 | E15: =D15-C15+1 -> 28 | F15: =CEILING(B15/E15,1) -> 3 | G15: 2 | H15: =F15*G15 -> 6 | I15: =CEILING(B15/F15,1) -> 26
A16: T12. Gasfitería | B16: ='Carta Gantt'!H53 -> 1 | C16: 10 | D16: 30 | E16: =D16-C16+1 -> 21 | F16: =CEILING(B16/E16,1) -> 1 | G16: 2 | H16: =F16*G16 -> 2 | I16: =CEILING(B16/F16,1) -> 1
A17: T13. Limpieza / Retiro escombros | B17: ='Carta Gantt'!H54 -> 1 | C17: 1 | D17: 60 | E17: =D17-C17+1 -> 60 | F17: =CEILING(B17/E17,1) -> 1 | G17: 1 | H17: =F17*G17 -> 1 | I17: =CEILING(B17/F17,1) -> 1
A19: TOTAL personas-día del programa (suma dotación x duración real): | B19: =H4*I4+H5*I5+H6*I6+H7*I7+H8*I8+H9*I9+H10*I10+H11*I11+H12*I12+H13*I13+H14*I14+H15*I15+H16*I16+H17*I17 -> 583

Sheet Dotación Diaria
A1: DOTACIÓN DE PERSONAL POR DÍA (consolidada por cuadrilla)
A3: Día | B3: Personas en obra
A4: 1 | B4: =(('Resumen Cuadrillas'!C4<=1)*('Resumen Cuadrillas'!D4>=1)*'Resumen Cuadrillas'!H4)+(('Resumen Cuadrillas'!C5<=1)*('Resumen Cuadrillas'!D5>=1)*'Resumen Cuadrillas'!H5)+(('Resumen Cuadrillas'!C6<=1)*('Resumen Cuadrillas'!D6>=1)*'Resumen Cuadrillas'!H6)+(('Resumen Cuadrillas'!C7<=1)*('Resumen Cuadrillas'!D7>=1)*'Resumen Cuadrillas'!H7)+(('Resumen Cuadrillas'!C8<=1)*('Resumen Cuadrillas'!D8>=1)*'Resumen Cuadrillas'!H8)+(('Resumen Cuadrillas'!C9<=1)*('Resumen Cuadrillas'!D9>=1)*'Resumen Cuadrillas'!H9)+(('Resumen Cuadrillas'!C10<=1)*('Resumen Cuadrillas'!D10>=1)*'Resumen Cuadrillas'!H10)+(('Resumen Cuadrillas'!C11<=1)*('Resumen Cuadrillas'!D11>=1)*'Resumen Cuadrillas'!H11)+(('Resumen Cuadrillas'!C12<=1)*('Resumen Cuadrillas'!D12>=1)*'Resumen Cuadrillas'!H12)+(('Resumen Cuadrillas'!C13<=1)*('Resumen Cuadrillas'!D13>=1)*'Resumen Cuadrillas'!H13)+(('Resumen Cuadrillas'!C14<=1)*('Resumen Cuadrillas'!D14>=1)*'Resumen Cuadrillas'!H14)+(('Resumen Cuadrillas'!C15<=1)*('Resumen Cuadrillas'!D15>=1)*'Resumen Cuadrillas'!H15)+(('Resumen Cuadrillas'!C16<=1)*('Resumen Cuadrillas'!D16>=1)*'Resumen Cuadrillas'!H16)+(('Resumen Cuadrillas'!C17<=1)*('Resumen Cuadrillas'!D17>=1)*'Resumen Cuadrillas'!H17) -> 9
A5: 2 | B5: =(('Resumen Cuadrillas'!C4<=2)*('Resumen Cuadrillas'!D4>=2)*'Resumen Cuadrillas'!H4)+(('Resumen Cuadrillas'!C5<=2)*('Resumen Cuadrillas'!D5>=2)*'Resumen Cuadrillas'!H5)+(('Resumen Cuadrillas'!C6<=2)*('Resumen Cuadrillas'!D6>=2)*'Resumen Cuadrillas'!H6)+(('Resumen Cuadrillas'!C7<=2)*('Resumen Cuadrillas'!D7>=2)*'Resumen Cuadrillas'!H7)+(('Resumen Cuadrillas'!C8<=2)*('Resumen Cuadrillas'!D8>=2)*'Resumen Cuadrillas'!H8)+(('Resumen Cuadrillas'!C9<=2)*('Resumen Cuadrillas'!D9>=2)*'Resumen Cuadrillas'!H9)+(('Resumen Cuadrillas'!C10<=2)*('Resumen Cuadrillas'!D10>=2)*'Resumen Cuadrillas'!H10)+(('Resumen Cuadrillas'!C11<=2)*('Resumen Cuadrillas'!D11>=2)*'Resumen Cuadrillas'!H11)+(('Resumen Cuadrillas'!C12<=2)*('Resumen Cuadrillas'!D12>=2)*'Resumen Cuadrillas'!H12)+(('Resumen Cuadrillas'!C13<=2)*('Resumen Cuadrillas'!D13>=2)*'Resumen Cuadrillas'!H13)+(('Resumen Cuadrillas'!C14<=2)*('Resumen Cuadrillas'!D14>=2)*'Resumen Cuadrillas'!H14)+(('Resumen Cuadrillas'!C15<=2)*('Resumen Cuadrillas'!D15>=2)*'Resumen Cuadrillas'!H15)+(('Resumen Cuadrillas'!C16<=2)*('Resumen Cuadrillas'!D16>=2)*'Resumen Cuadrillas'!H16)+(('Resumen Cuadrillas'!C17<=2)*('Resumen Cuadrillas'!D17>=2)*'Resumen Cuadrillas'!H17) -> 9
A6: 3 | B6: =(('Resumen Cuadrillas'!C4<=3)*('Resumen Cuadrillas'!D4>=3)*'Resumen Cuadrillas'!H4)+(('Resumen Cuadrillas'!C5<=3)*('Resumen Cuadrillas'!D5>=3)*'Resumen Cuadrillas'!H5)+(('Resumen Cuadrillas'!C6<=3)*('Resumen Cuadrillas'!D6>=3)*'Resumen Cuadrillas'!H6)+(('Resumen Cuadrillas'!C7<=3)*('Resumen Cuadrillas'!D7>=3)*'Resumen Cuadrillas'!H7)+(('Resumen Cuadrillas'!C8<=3)*('Resumen Cuadrillas'!D8>=3)*'Resumen Cuadrillas'!H8)+(('Resumen Cuadrillas'!C9<=3)*('Resumen Cuadrillas'!D9>=3)*'Resumen Cuadrillas'!H9)+(('Resumen Cuadrillas'!C10<=3)*('Resumen Cuadrillas'!D10>=3)*'Resumen Cuadrillas'!H10)+(('Resumen Cuadrillas'!C11<=3)*('Resumen Cuadrillas'!D11>=3)*'Resumen Cuadrillas'!H11)+(('Resumen Cuadrillas'!C12<=3)*('Resumen Cuadrillas'!D12>=3)*'Resumen Cuadrillas'!H12)+(('Resumen Cuadrillas'!C13<=3)*('Resumen Cuadrillas'!D13>=3)*'Resumen Cuadrillas'!H13)+(('Resumen Cuadrillas'!C14<=3)*('Resumen Cuadrillas'!D14>=3)*'Resumen Cuadrillas'!H14)+(('Resumen Cuadrillas'!C15<=3)*('Resumen Cuadrillas'!D15>=3)*'Resumen Cuadrillas'!H15)+(('Resumen Cuadrillas'!C16<=3)*('Resumen Cuadrillas'!D16>=3)*'Resumen Cuadrillas'!H16)+(('Resumen Cuadrillas'!C17<=3)*('Resumen Cuadrillas'!D17>=3)*'Resumen Cuadrillas'!H17) -> 15
A7: 4 | B7: =(('Resumen Cuadrillas'!C4<=4)*('Resumen Cuadrillas'!D4>=4)*'Resumen Cuadrillas'!H4)+(('Resumen Cuadrillas'!C5<=4)*('Resumen Cuadrillas'!D5>=4)*'Resumen Cuadrillas'!H5)+(('Resumen Cuadrillas'!C6<=4)*('Resumen Cuadrillas'!D6>=4)*'Resumen Cuadrillas'!H6)+(('Resumen Cuadrillas'!C7<=4)*('Resumen Cuadrillas'!D7>=4)*'Resumen Cuadrillas'!H7)+(('Resumen Cuadrillas'!C8<=4)*('Resumen Cuadrillas'!D8>=4)*'Resumen Cuadrillas'!H8)+(('Resumen Cuadrillas'!C9<=4)*('Resumen Cuadrillas'!D9>=4)*'Resumen Cuadrillas'!H9)+(('Resumen Cuadrillas'!C10<=4)*('Resumen Cuadrillas'!D10>=4)*'Resumen Cuadrillas'!H10)+(('Resumen Cuadrillas'!C11<=4)*('Resumen Cuadrillas'!D11>=4)*'Resumen Cuadrillas'!H11)+(('Resumen Cuadrillas'!C12<=4)*('Resumen Cuadrillas'!D12>=4)*'Resumen Cuadrillas'!H12)+(('Resumen Cuadrillas'!C13<=4)*('Resumen Cuadrillas'!D13>=4)*'Resumen Cuadrillas'!H13)+(('Resumen Cuadrillas'!C14<=4)*('Resumen Cuadrillas'!D14>=4)*'Resumen Cuadrillas'!H14)+(('Resumen Cuadrillas'!C15<=4)*('Resumen Cuadrillas'!D15>=4)*'Resumen Cuadrillas'!H15)+(('Resumen Cuadrillas'!C16<=4)*('Resumen Cuadrillas'!D16>=4)*'Resumen Cuadrillas'!H16)+(('Resumen Cuadrillas'!C17<=4)*('Resumen Cuadrillas'!D17>=4)*'Resumen Cuadrillas'!H17) -> 19
A8: 5 | B8: =(('Resumen Cuadrillas'!C4<=5)*('Resumen Cuadrillas'!D4>=5)*'Resumen Cuadrillas'!H4)+(('Resumen Cuadrillas'!C5<=5)*('Resumen Cuadrillas'!D5>=5)*'Resumen Cuadrillas'!H5)+(('Resumen Cuadrillas'!C6<=5)*('Resumen Cuadrillas'!D6>=5)*'Resumen Cuadrillas'!H6)+(('Resumen Cuadrillas'!C7<=5)*('Resumen Cuadrillas'!D7>=5)*'Resumen Cuadrillas'!H7)+(('Resumen Cuadrillas'!C8<=5)*('Resumen Cuadrillas'!D8>=5)*'Resumen Cuadrillas'!H8)+(('Resumen Cuadrillas'!C9<=5)*('Resumen Cuadrillas'!D9>=5)*'Resumen Cuadrillas'!H9)+(('Resumen Cuadrillas'!C10<=5)*('Resumen Cuadrillas'!D10>=5)*'Resumen Cuadrillas'!H10)+(('Resumen Cuadrillas'!C11<=5)*('Resumen Cuadrillas'!D11>=5)*'Resumen Cuadrillas'!H11)+(('Resumen Cuadrillas'!C12<=5)*('Resumen Cuadrillas'!D12>=5)*'Resumen Cuadrillas'!H12)+(('Resumen Cuadrillas'!C13<=5)*('Resumen Cuadrillas'!D13>=5)*'Resumen Cuadrillas'!H13)+(('Resumen Cuadrillas'!C14<=5)*('Resumen Cuadrillas'!D14>=5)*'Resumen Cuadrillas'!H14)+(('Resumen Cuadrillas'!C15<=5)*('Resumen Cuadrillas'!D15>=5)*'Resumen Cuadrillas'!H15)+(('Resumen Cuadrillas'!C16<=5)*('Resumen Cuadrillas'!D16>=5)*'Resumen Cuadrillas'!H16)+(('Resumen Cuadrillas'!C17<=5)*('Resumen Cuadrillas'!D17>=5)*'Resumen Cuadrillas'!H17) -> 19
A9: 6 | B9: =(('Resumen Cuadrillas'!C4<=6)*('Resumen Cuadrillas'!D4>=6)*'Resumen Cuadrillas'!H4)+(('Resumen Cuadrillas'!C5<=6)*('Resumen Cuadrillas'!D5>=6)*'Resumen Cuadrillas'!H5)+(('Resumen Cuadrillas'!C6<=6)*('Resumen Cuadrillas'!D6>=6)*'Resumen Cuadrillas'!H6)+(('Resumen Cuadrillas'!C7<=6)*('Resumen Cuadrillas'!D7>=6)*'Resumen Cuadrillas'!H7)+(('Resumen Cuadrillas'!C8<=6)*('Resumen Cuadrillas'!D8>=6)*'Resumen Cuadrillas'!H8)+(('Resumen Cuadrillas'!C9<=6)*('Resumen Cuadrillas'!D9>=6)*'Resumen Cuadrillas'!H9)+(('Resumen Cuadrillas'!C10<=6)*('Resumen Cuadrillas'!D10>=6)*'Resumen Cuadrillas'!H10)+(('Resumen Cuadrillas'!C11<=6)*('Resumen Cuadrillas'!D11>=6)*'Resumen Cuadrillas'!H11)+(('Resumen Cuadrillas'!C12<=6)*('Resumen Cuadrillas'!D12>=6)*'Resumen Cuadrillas'!H12)+(('Resumen Cuadrillas'!C13<=6)*('Resumen Cuadrillas'!D13>=6)*'Resumen Cuadrillas'!H13)+(('Resumen Cuadrillas'!C14<=6)*('Resumen Cuadrillas'!D14>=6)*'Resumen Cuadrillas'!H14)+(('Resumen Cuadrillas'!C15<=6)*('Resumen Cuadrillas'!D15>=6)*'Resumen Cuadrillas'!H15)+(('Resumen Cuadrillas'!C16<=6)*('Resumen Cuadrillas'!D16>=6)*'Resumen Cuadrillas'!H16)+(('Resumen Cuadrillas'!C17<=6)*('Resumen Cuadrillas'!D17>=6)*'Resumen Cuadrillas'!H17) -> 21
A10: 7 | B10: =(('Resumen Cuadrillas'!C4<=7)*('Resumen Cuadrillas'!D4>=7)*'Resumen Cuadrillas'!H4)+(('Resumen Cuadrillas'!C5<=7)*('Resumen Cuadrillas'!D5>=7)*'Resumen Cuadrillas'!H5)+(('Resumen Cuadrillas'!C6<=7)*('Resumen Cuadrillas'!D6>=7)*'Resumen Cuadrillas'!H6)+(('Resumen Cuadrillas'!C7<=7)*('Resumen Cuadrillas'!D7>=7)*'Resumen Cuadrillas'!H7)+(('Resumen Cuadrillas'!C8<=7)*('Resumen Cuadrillas'!D8>=7)*'Resumen Cuadrillas'!H8)+(('Resumen Cuadrillas'!C9<=7)*('Resumen Cuadrillas'!D9>=7)*'Resumen Cuadrillas'!H9)+(('Resumen Cuadrillas'!C10<=7)*('Resumen Cuadrillas'!D10>=7)*'Resumen Cuadrillas'!H10)+(('Resumen Cuadrillas'!C11<=7)*('Resumen Cuadrillas'!D11>=7)*'Resumen Cuadrillas'!H11)+(('Resumen Cuadrillas'!C12<=7)*('Resumen Cuadrillas'!D12>=7)*'Resumen Cuadrillas'!H12)+(('Resumen Cuadrillas'!C13<=7)*('Resumen Cuadrillas'!D13>=7)*'Resumen Cuadrillas'!H13)+(('Resumen Cuadrillas'!C14<=7)*('Resumen Cuadrillas'!D14>=7)*'Resumen Cuadrillas'!H14)+(('Resumen Cuadrillas'!C15<=7)*('Resumen Cuadrillas'!D15>=7)*'Resumen Cuadrillas'!H15)+(('Resumen Cuadrillas'!C16<=7)*('Resumen Cuadrillas'!D16>=7)*'Resumen Cuadrillas'!H16)+(('Resumen Cuadrillas'!C17<=7)*('Resumen Cuadrillas'!D17>=7)*'Resumen Cuadrillas'!H17) -> 21
A11: 8 | B11: =(('Resumen Cuadrillas'!C4<=8)*('Resumen Cuadrillas'!D4>=8)*'Resumen Cuadrillas'!H4)+(('Resumen Cuadrillas'!C5<=8)*('Resumen Cuadrillas'!D5>=8)*'Resumen Cuadrillas'!H5)+(('Resumen Cuadrillas'!C6<=8)*('Resumen Cuadrillas'!D6>=8)*'Resumen Cuadrillas'!H6)+(('Resumen Cuadrillas'!C7<=8)*('Resumen Cuadrillas'!D7>=8)*'Resumen Cuadrillas'!H7)+(('Resumen Cuadrillas'!C8<=8)*('Resumen Cuadrillas'!D8>=8)*'Resumen Cuadrillas'!H8)+(('Resumen Cuadrillas'!C9<=8)*('Resumen Cuadrillas'!D9>=8)*'Resumen Cuadrillas'!H9)+(('Resumen Cuadrillas'!C10<=8)*('Resumen Cuadrillas'!D10>=8)*'Resumen Cuadrillas'!H10)+(('Resumen Cuadrillas'!C11<=8)*('Resumen Cuadrillas'!D11>=8)*'Resumen Cuadrillas'!H11)+(('Resumen Cuadrillas'!C12<=8)*('Resumen Cuadrillas'!D12>=8)*'Resumen Cuadrillas'!H12)+(('Resumen Cuadrillas'!C13<=8)*('Resumen Cuadrillas'!D13>=8)*'Resumen Cuadrillas'!H13)+(('Resumen Cuadrillas'!C14<=8)*('Resumen Cuadrillas'!D14>=8)*'Resumen Cuadrillas'!H14)+(('Resumen Cuadrillas'!C15<=8)*('Resumen Cuadrillas'!D15>=8)*'Resumen Cuadrillas'!H15)+(('Resumen Cuadrillas'!C16<=8)*('Resumen Cuadrillas'!D16>=8)*'Resumen Cuadrillas'!H16)+(('Resumen Cuadrillas'!C17<=8)*('Resumen Cuadrillas'!D17>=8)*'Resumen Cuadrillas'!H17) -> 21
A12: 9 | B12: =(('Resumen Cuadrillas'!C4<=9)*('Resumen Cuadrillas'!D4>=9)*'Resumen Cuadrillas'!H4)+(('Resumen Cuadrillas'!C5<=9)*('Resumen Cuadrillas'!D5>=9)*'Resumen Cuadrillas'!H5)+(('Resumen Cuadrillas'!C6<=9)*('Resumen Cuadrillas'!D6>=9)*'Resumen Cuadrillas'!H6)+(('Resumen Cuadrillas'!C7<=9)*('Resumen Cuadrillas'!D7>=9)*'Resumen Cuadrillas'!H7)+(('Resumen Cuadrillas'!C8<=9)*('Resumen Cuadrillas'!D8>=9)*'Resumen Cuadrillas'!H8)+(('Resumen Cuadrillas'!C9<=9)*('Resumen Cuadrillas'!D9>=9)*'Resumen Cuadrillas'!H9)+(('Resumen Cuadrillas'!C10<=9)*('Resumen Cuadrillas'!D10>=9)*'Resumen Cuadrillas'!H10)+(('Resumen Cuadrillas'!C11<=9)*('Resumen Cuadrillas'!D11>=9)*'Resumen Cuadrillas'!H11)+(('Resumen Cuadrillas'!C12<=9)*('Resumen Cuadrillas'!D12>=9)*'Resumen Cuadrillas'!H12)+(('Resumen Cuadrillas'!C13<=9)*('Resumen Cuadrillas'!D13>=9)*'Resumen Cuadrillas'!H13)+(('Resumen Cuadrillas'!C14<=9)*('Resumen Cuadrillas'!D14>=9)*'Resumen Cuadrillas'!H14)+(('Resumen Cuadrillas'!C15<=9)*('Resumen Cuadrillas'!D15>=9)*'Resumen Cuadrillas'!H15)+(('Resumen Cuadrillas'!C16<=9)*('Resumen Cuadrillas'!D16>=9)*'Resumen Cuadrillas'!H16)+(('Resumen Cuadrillas'!C17<=9)*('Resumen Cuadrillas'!D17>=9)*'Resumen Cuadrillas'!H17) -> 21
A13: 10 | B13: =(('Resumen Cuadrillas'!C4<=10)*('Resumen Cuadrillas'!D4>=10)*'Resumen Cuadrillas'!H4)+(('Resumen Cuadrillas'!C5<=10)*('Resumen Cuadrillas'!D5>=10)*'Resumen Cuadrillas'!H5)+(('Resumen Cuadrillas'!C6<=10)*('Resumen Cuadrillas'!D6>=10)*'Resumen Cuadrillas'!H6)+(('Resumen Cuadrillas'!C7<=10)*('Resumen Cuadrillas'!D7>=10)*'Resumen Cuadrillas'!H7)+(('Resumen Cuadrillas'!C8<=10)*('Resumen Cuadrillas'!D8>=10)*'Resumen Cuadrillas'!H8)+(('Resumen Cuadrillas'!C9<=10)*('Resumen Cuadrillas'!D9>=10)*'Resumen Cuadrillas'!H9)+(('Resumen Cuadrillas'!C10<=10)*('Resumen Cuadrillas'!D10>=10)*'Resumen Cuadrillas'!H10)+(('Resumen Cuadrillas'!C11<=10)*('Resumen Cuadrillas'!D11>=10)*'Resumen Cuadrillas'!H11)+(('Resumen Cuadrillas'!C12<=10)*('Resumen Cuadrillas'!D12>=10)*'Resumen Cuadrillas'!H12)+(('Resumen Cuadrillas'!C13<=10)*('Resumen Cuadrillas'!D13>=10)*'Resumen Cuadrillas'!H13)+(('Resumen Cuadrillas'!C14<=10)*('Resumen Cuadrillas'!D14>=10)*'Resumen Cuadrillas'!H14)+(('Resumen Cuadrillas'!C15<=10)*('Resumen Cuadrillas'!D15>=10)*'Resumen Cuadrillas'!H15)+(('Resumen Cuadrillas'!C16<=10)*('Resumen Cuadrillas'!D16>=10)*'Resumen Cuadrillas'!H16)+(('Resumen Cuadrillas'!C17<=10)*('Resumen Cuadrillas'!D17>=10)*'Resumen Cuadrillas'!H17) -> 23
A14: 11 | B14: =(('Resumen Cuadrillas'!C4<=11)*('Resumen Cuadrillas'!D4>=11)*'Resumen Cuadrillas'!H4)+(('Resumen Cuadrillas'!C5<=11)*('Resumen Cuadrillas'!D5>=11)*'Resumen Cuadrillas'!H5)+(('Resumen Cuadrillas'!C6<=11)*('Resumen Cuadrillas'!D6>=11)*'Resumen Cuadrillas'!H6)+(('Resumen Cuadrillas'!C7<=11)*('Resumen Cuadrillas'!D7>=11)*'Resumen Cuadrillas'!H7)+(('Resumen Cuadrillas'!C8<=11)*('Resumen Cuadrillas'!D8>=11)*'Resumen Cuadrillas'!H8)+(('Resumen Cuadrillas'!C9<=11)*('Resumen Cuadrillas'!D9>=11)*'Resumen Cuadrillas'!H9)+(('Resumen Cuadrillas'!C10<=11)*('Resumen Cuadrillas'!D10>=11)*'Resumen Cuadrillas'!H10)+(('Resumen Cuadrillas'!C11<=11)*('Resumen Cuadrillas'!D11>=11)*'Resumen Cuadrillas'!H11)+(('Resumen Cuadrillas'!C12<=11)*('Resumen Cuadrillas'!D12>=11)*'Resumen Cuadrillas'!H12)+(('Resumen Cuadrillas'!C13<=11)*('Resumen Cuadrillas'!D13>=11)*'Resumen Cuadrillas'!H13)+(('Resumen Cuadrillas'!C14<=11)*('Resumen Cuadrillas'!D14>=11)*'Resumen Cuadrillas'!H14)+(('Resumen Cuadrillas'!C15<=11)*('Resumen Cuadrillas'!D15>=11)*'Resumen Cuadrillas'!H15)+(('Resumen Cuadrillas'!C16<=11)*('Resumen Cuadrillas'!D16>=11)*'Resumen Cuadrillas'!H16)+(('Resumen Cuadrillas'!C17<=11)*('Resumen Cuadrillas'!D17>=11)*'Resumen Cuadrillas'!H17) -> 19
A15: 12 | B15: =(('Resumen Cuadrillas'!C4<=12)*('Resumen Cuadrillas'!D4>=12)*'Resumen Cuadrillas'!H4)+(('Resumen Cuadrillas'!C5<=12)*('Resumen Cuadrillas'!D5>=12)*'Resumen Cuadrillas'!H5)+(('Resumen Cuadrillas'!C6<=12)*('Resumen Cuadrillas'!D6>=12)*'Resumen Cuadrillas'!H6)+(('Resumen Cuadrillas'!C7<=12)*('Resumen Cuadrillas'!D7>=12)*'Resumen Cuadrillas'!H7)+(('Resumen Cuadrillas'!C8<=12)*('Resumen Cuadrillas'!D8>=12)*'Resumen Cuadrillas'!H8)+(('Resumen Cuadrillas'!C9<=12)*('Resumen Cuadrillas'!D9>=12)*'Resumen Cuadrillas'!H9)+(('Resumen Cuadrillas'!C10<=12)*('Resumen Cuadrillas'!D10>=12)*'Resumen Cuadrillas'!H10)+(('Resumen Cuadrillas'!C11<=12)*('Resumen Cuadrillas'!D11>=12)*'Resumen Cuadrillas'!H11)+(('Resumen Cuadrillas'!C12<=12)*('Resumen Cuadrillas'!D12>=12)*'Resumen Cuadrillas'!H12)+(('Resumen Cuadrillas'!C13<=12)*('Resumen Cuadrillas'!D13>=12)*'Resumen Cuadrillas'!H13)+(('Resumen Cuadrillas'!C14<=12)*('Resumen Cuadrillas'!D14>=12)*'Resumen Cuadrillas'!H14)+(('Resumen Cuadrillas'!C15<=12)*('Resumen Cuadrillas'!D15>=12)*'Resumen Cuadrillas'!H15)+(('Resumen Cuadrillas'!C16<=12)*('Resumen Cuadrillas'!D16>=12)*'Resumen Cuadrillas'!H16)+(('Resumen Cuadrillas'!C17<=12)*('Resumen Cuadrillas'!D17>=12)*'Resumen Cuadrillas'!H17) -> 26
A16: 13 | B16: =(('Resumen Cuadrillas'!C4<=13)*('Resumen Cuadrillas'!D4>=13)*'Resumen Cuadrillas'!H4)+(('Resumen Cuadrillas'!C5<=13)*('Resumen Cuadrillas'!D5>=13)*'Resumen Cuadrillas'!H5)+(('Resumen Cuadrillas'!C6<=13)*('Resumen Cuadrillas'!D6>=13)*'Resumen Cuadrillas'!H6)+(('Resumen Cuadrillas'!C7<=13)*('Resumen Cuadrillas'!D7>=13)*'Resumen Cuadrillas'!H7)+(('Resumen Cuadrillas'!C8<=13)*('Resumen Cuadrillas'!D8>=13)*'Resumen Cuadrillas'!H8)+(('Resumen Cuadrillas'!C9<=13)*('Resumen Cuadrillas'!D9>=13)*'Resumen Cuadrillas'!H9)+(('Resumen Cuadrillas'!C10<=13)*('Resumen Cuadrillas'!D10>=13)*'Resumen Cuadrillas'!H10)+(('Resumen Cuadrillas'!C11<=13)*('Resumen Cuadrillas'!D11>=13)*'Resumen Cuadrillas'!H11)+(('Resumen Cuadrillas'!C12<=13)*('Resumen Cuadrillas'!D12>=13)*'Resumen Cuadrillas'!H12)+(('Resumen Cuadrillas'!C13<=13)*('Resumen Cuadrillas'!D13>=13)*'Resumen Cuadrillas'!H13)+(('Resumen Cuadrillas'!C14<=13)*('Resumen Cuadrillas'!D14>=13)*'Resumen Cuadrillas'!H14)+(('Resumen Cuadrillas'!C15<=13)*('Resumen Cuadrillas'!D15>=13)*'Resumen Cuadrillas'!H15)+(('Resumen Cuadrillas'!C16<=13)*('Resumen Cuadrillas'!D16>=13)*'Resumen Cuadrillas'!H16)+(('Resumen Cuadrillas'!C17<=13)*('Resumen Cuadrillas'!D17>=13)*'Resumen Cuadrillas'!H17) -> 26
A17: 14 | B17: =(('Resumen Cuadrillas'!C4<=14)*('Resumen Cuadrillas'!D4>=14)*'Resumen Cuadrillas'!H4)+(('Resumen Cuadrillas'!C5<=14)*('Resumen Cuadrillas'!D5>=14)*'Resumen Cuadrillas'!H5)+(('Resumen Cuadrillas'!C6<=14)*('Resumen Cuadrillas'!D6>=14)*'Resumen Cuadrillas'!H6)+(('Resumen Cuadrillas'!C7<=14)*('Resumen Cuadrillas'!D7>=14)*'Resumen Cuadrillas'!H7)+(('Resumen Cuadrillas'!C8<=14)*('Resumen Cuadrillas'!D8>=14)*'Resumen Cuadrillas'!H8)+(('Resumen Cuadrillas'!C9<=14)*('Resumen Cuadrillas'!D9>=14)*'Resumen Cuadrillas'!H9)+(('Resumen Cuadrillas'!C10<=14)*('Resumen Cuadrillas'!D10>=14)*'Resumen Cuadrillas'!H10)+(('Resumen Cuadrillas'!C11<=14)*('Resumen Cuadrillas'!D11>=14)*'Resumen Cuadrillas'!H11)+(('Resumen Cuadrillas'!C12<=14)*('Resumen Cuadrillas'!D12>=14)*'Resumen Cuadrillas'!H12)+(('Resumen Cuadrillas'!C13<=14)*('Resumen Cuadrillas'!D13>=14)*'Resumen Cuadrillas'!H13)+(('Resumen Cuadrillas'!C14<=14)*('Resumen Cuadrillas'!D14>=14)*'Resumen Cuadrillas'!H14)+(('Resumen Cuadrillas'!C15<=14)*('Resumen Cuadrillas'!D15>=14)*'Resumen Cuadrillas'!H15)+(('Resumen Cuadrillas'!C16<=14)*('Resumen Cuadrillas'!D16>=14)*'Resumen Cuadrillas'!H16)+(('Resumen Cuadrillas'!C17<=14)*('Resumen Cuadrillas'!D17>=14)*'Resumen Cuadrillas'!H17) -> 22
A18: 15 | B18: =(('Resumen Cuadrillas'!C4<=15)*('Resumen Cuadrillas'!D4>=15)*'Resumen Cuadrillas'!H4)+(('Resumen Cuadrillas'!C5<=15)*('Resumen Cuadrillas'!D5>=15)*'Resumen Cuadrillas'!H5)+(('Resumen Cuadrillas'!C6<=15)*('Resumen Cuadrillas'!D6>=15)*'Resumen Cuadrillas'!H6)+(('Resumen Cuadrillas'!C7<=15)*('Resumen Cuadrillas'!D7>=15)*'Resumen Cuadrillas'!H7)+(('Resumen Cuadrillas'!C8<=15)*('Resumen Cuadrillas'!D8>=15)*'Resumen Cuadrillas'!H8)+(('Resumen Cuadrillas'!C9<=15)*('Resumen Cuadrillas'!D9>=15)*'Resumen Cuadrillas'!H9)+(('Resumen Cuadrillas'!C10<=15)*('Resumen Cuadrillas'!D10>=15)*'Resumen Cuadrillas'!H10)+(('Resumen Cuadrillas'!C11<=15)*('Resumen Cuadrillas'!D11>=15)*'Resumen Cuadrillas'!H11)+(('Resumen Cuadrillas'!C12<=15)*('Resumen Cuadrillas'!D12>=15)*'Resumen Cuadrillas'!H12)+(('Resumen Cuadrillas'!C13<=15)*('Resumen Cuadrillas'!D13>=15)*'Resumen Cuadrillas'!H13)+(('Resumen Cuadrillas'!C14<=15)*('Resumen Cuadrillas'!D14>=15)*'Resumen Cuadrillas'!H14)+(('Resumen Cuadrillas'!C15<=15)*('Resumen Cuadrillas'!D15>=15)*'Resumen Cuadrillas'!H15)+(('Resumen Cuadrillas'!C16<=15)*('Resumen Cuadrillas'!D16>=15)*'Resumen Cuadrillas'!H16)+(('Resumen Cuadrillas'!C17<=15)*('Resumen Cuadrillas'!D17>=15)*'Resumen Cuadrillas'!H17) -> 22
A19: 16 | B19: =(('Resumen Cuadrillas'!C4<=16)*('Resumen Cuadrillas'!D4>=16)*'Resumen Cuadrillas'!H4)+(('Resumen Cuadrillas'!C5<=16)*('Resumen Cuadrillas'!D5>=16)*'Resumen Cuadrillas'!H5)+(('Resumen Cuadrillas'!C6<=16)*('Resumen Cuadrillas'!D6>=16)*'Resumen Cuadrillas'!H6)+(('Resumen Cuadrillas'!C7<=16)*('Resumen Cuadrillas'!D7>=16)*'Resumen Cuadrillas'!H7)+(('Resumen Cuadrillas'!C8<=16)*('Resumen Cuadrillas'!D8>=16)*'Resumen Cuadrillas'!H8)+(('Resumen Cuadrillas'!C9<=16)*('Resumen Cuadrillas'!D9>=16)*'Resumen Cuadrillas'!H9)+(('Resumen Cuadrillas'!C10<=16)*('Resumen Cuadrillas'!D10>=16)*'Resumen Cuadrillas'!H10)+(('Resumen Cuadrillas'!C11<=16)*('Resumen Cuadrillas'!D11>=16)*'Resumen Cuadrillas'!H11)+(('Resumen Cuadrillas'!C12<=16)*('Resumen Cuadrillas'!D12>=16)*'Resumen Cuadrillas'!H12)+(('Resumen Cuadrillas'!C13<=16)*('Resumen Cuadrillas'!D13>=16)*'Resumen Cuadrillas'!H13)+(('Resumen Cuadrillas'!C14<=16)*('Resumen Cuadrillas'!D14>=16)*'Resumen Cuadrillas'!H14)+(('Resumen Cuadrillas'!C15<=16)*('Resumen Cuadrillas'!D15>=16)*'Resumen Cuadrillas'!H15)+(('Resumen Cuadrillas'!C16<=16)*('Resumen Cuadrillas'!D16>=16)*'Resumen Cuadrillas'!H16)+(('Resumen Cuadrillas'!C17<=16)*('Resumen Cuadrillas'!D17>=16)*'Resumen Cuadrillas'!H17) -> 22
A20: 17 | B20: =(('Resumen Cuadrillas'!C4<=17)*('Resumen Cuadrillas'!D4>=17)*'Resumen Cuadrillas'!H4)+(('Resumen Cuadrillas'!C5<=17)*('Resumen Cuadrillas'!D5>=17)*'Resumen Cuadrillas'!H5)+(('Resumen Cuadrillas'!C6<=17)*('Resumen Cuadrillas'!D6>=17)*'Resumen Cuadrillas'!H6)+(('Resumen Cuadrillas'!C7<=17)*('Resumen Cuadrillas'!D7>=17)*'Resumen Cuadrillas'!H7)+(('Resumen Cuadrillas'!C8<=17)*('Resumen Cuadrillas'!D8>=17)*'Resumen Cuadrillas'!H8)+(('Resumen Cuadrillas'!C9<=17)*('Resumen Cuadrillas'!D9>=17)*'Resumen Cuadrillas'!H9)+(('Resumen Cuadrillas'!C10<=17)*('Resumen Cuadrillas'!D10>=17)*'Resumen Cuadrillas'!H10)+(('Resumen Cuadrillas'!C11<=17)*('Resumen Cuadrillas'!D11>=17)*'Resumen Cuadrillas'!H11)+(('Resumen Cuadrillas'!C12<=17)*('Resumen Cuadrillas'!D12>=17)*'Resumen Cuadrillas'!H12)+(('Resumen Cuadrillas'!C13<=17)*('Resumen Cuadrillas'!D13>=17)*'Resumen Cuadrillas'!H13)+(('Resumen Cuadrillas'!C14<=17)*('Resumen Cuadrillas'!D14>=17)*'Resumen Cuadrillas'!H14)+(('Resumen Cuadrillas'!C15<=17)*('Resumen Cuadrillas'!D15>=17)*'Resumen Cuadrillas'!H15)+(('Resumen Cuadrillas'!C16<=17)*('Resumen Cuadrillas'!D16>=17)*'Resumen Cuadrillas'!H16)+(('Resumen Cuadrillas'!C17<=17)*('Resumen Cuadrillas'!D17>=17)*'Resumen Cuadrillas'!H17) -> 22
A21: 18 | B21: =(('Resumen Cuadrillas'!C4<=18)*('Resumen Cuadrillas'!D4>=18)*'Resumen Cuadrillas'!H4)+(('Resumen Cuadrillas'!C5<=18)*('Resumen Cuadrillas'!D5>=18)*'Resumen Cuadrillas'!H5)+(('Resumen Cuadrillas'!C6<=18)*('Resumen Cuadrillas'!D6>=18)*'Resumen Cuadrillas'!H6)+(('Resumen Cuadrillas'!C7<=18)*('Resumen Cuadrillas'!D7>=18)*'Resumen Cuadrillas'!H7)+(('Resumen Cuadrillas'!C8<=18)*('Resumen Cuadrillas'!D8>=18)*'Resumen Cuadrillas'!H8)+(('Resumen Cuadrillas'!C9<=18)*('Resumen Cuadrillas'!D9>=18)*'Resumen Cuadrillas'!H9)+(('Resumen Cuadrillas'!C10<=18)*('Resumen Cuadrillas'!D10>=18)*'Resumen Cuadrillas'!H10)+(('Resumen Cuadrillas'!C11<=18)*('Resumen Cuadrillas'!D11>=18)*'Resumen Cuadrillas'!H11)+(('Resumen Cuadrillas'!C12<=18)*('Resumen Cuadrillas'!D12>=18)*'Resumen Cuadrillas'!H12)+(('Resumen Cuadrillas'!C13<=18)*('Resumen Cuadrillas'!D13>=18)*'Resumen Cuadrillas'!H13)+(('Resumen Cuadrillas'!C14<=18)*('Resumen Cuadrillas'!D14>=18)*'Resumen Cuadrillas'!H14)+(('Resumen Cuadrillas'!C15<=18)*('Resumen Cuadrillas'!D15>=18)*'Resumen Cuadrillas'!H15)+(('Resumen Cuadrillas'!C16<=18)*('Resumen Cuadrillas'!D16>=18)*'Resumen Cuadrillas'!H16)+(('Resumen Cuadrillas'!C17<=18)*('Resumen Cuadrillas'!D17>=18)*'Resumen Cuadrillas'!H17) -> 24
A22: 19 | B22: =(('Resumen Cuadrillas'!C4<=19)*('Resumen Cuadrillas'!D4>=19)*'Resumen Cuadrillas'!H4)+(('Resumen Cuadrillas'!C5<=19)*('Resumen Cuadrillas'!D5>=19)*'Resumen Cuadrillas'!H5)+(('Resumen Cuadrillas'!C6<=19)*('Resumen Cuadrillas'!D6>=19)*'Resumen Cuadrillas'!H6)+(('Resumen Cuadrillas'!C7<=19)*('Resumen Cuadrillas'!D7>=19)*'Resumen Cuadrillas'!H7)+(('Resumen Cuadrillas'!C8<=19)*('Resumen Cuadrillas'!D8>=19)*'Resumen Cuadrillas'!H8)+(('Resumen Cuadrillas'!C9<=19)*('Resumen Cuadrillas'!D9>=19)*'Resumen Cuadrillas'!H9)+(('Resumen Cuadrillas'!C10<=19)*('Resumen Cuadrillas'!D10>=19)*'Resumen Cuadrillas'!H10)+(('Resumen Cuadrillas'!C11<=19)*('Resumen Cuadrillas'!D11>=19)*'Resumen Cuadrillas'!H11)+(('Resumen Cuadrillas'!C12<=19)*('Resumen Cuadrillas'!D12>=19)*'Resumen Cuadrillas'!H12)+(('Resumen Cuadrillas'!C13<=19)*('Resumen Cuadrillas'!D13>=19)*'Resumen Cuadrillas'!H13)+(('Resumen Cuadrillas'!C14<=19)*('Resumen Cuadrillas'!D14>=19)*'Resumen Cuadrillas'!H14)+(('Resumen Cuadrillas'!C15<=19)*('Resumen Cuadrillas'!D15>=19)*'Resumen Cuadrillas'!H15)+(('Resumen Cuadrillas'!C16<=19)*('Resumen Cuadrillas'!D16>=19)*'Resumen Cuadrillas'!H16)+(('Resumen Cuadrillas'!C17<=19)*('Resumen Cuadrillas'!D17>=19)*'Resumen Cuadrillas'!H17) -> 24
A23: 20 | B23: =(('Resumen Cuadrillas'!C4<=20)*('Resumen Cuadrillas'!D4>=20)*'Resumen Cuadrillas'!H4)+(('Resumen Cuadrillas'!C5<=20)*('Resumen Cuadrillas'!D5>=20)*'Resumen Cuadrillas'!H5)+(('Resumen Cuadrillas'!C6<=20)*('Resumen Cuadrillas'!D6>=20)*'Resumen Cuadrillas'!H6)+(('Resumen Cuadrillas'!C7<=20)*('Resumen Cuadrillas'!D7>=20)*'Resumen Cuadrillas'!H7)+(('Resumen Cuadrillas'!C8<=20)*('Resumen Cuadrillas'!D8>=20)*'Resumen Cuadrillas'!H8)+(('Resumen Cuadrillas'!C9<=20)*('Resumen Cuadrillas'!D9>=20)*'Resumen Cuadrillas'!H9)+(('Resumen Cuadrillas'!C10<=20)*('Resumen Cuadrillas'!D10>=20)*'Resumen Cuadrillas'!H10)+(('Resumen Cuadrillas'!C11<=20)*('Resumen Cuadrillas'!D11>=20)*'Resumen Cuadrillas'!H11)+(('Resumen Cuadrillas'!C12<=20)*('Resumen Cuadrillas'!D12>=20)*'Resumen Cuadrillas'!H12)+(('Resumen Cuadrillas'!C13<=20)*('Resumen Cuadrillas'!D13>=20)*'Resumen Cuadrillas'!H13)+(('Resumen Cuadrillas'!C14<=20)*('Resumen Cuadrillas'!D14>=20)*'Resumen Cuadrillas'!H14)+(('Resumen Cuadrillas'!C15<=20)*('Resumen Cuadrillas'!D15>=20)*'Resumen Cuadrillas'!H15)+(('Resumen Cuadrillas'!C16<=20)*('Resumen Cuadrillas'!D16>=20)*'Resumen Cuadrillas'!H16)+(('Resumen Cuadrillas'!C17<=20)*('Resumen Cuadrillas'!D17>=20)*'Resumen Cuadrillas'!H17) -> 28
A24: 21 | B24: =(('Resumen Cuadrillas'!C4<=21)*('Resumen Cuadrillas'!D4>=21)*'Resumen Cuadrillas'!H4)+(('Resumen Cuadrillas'!C5<=21)*('Resumen Cuadrillas'!D5>=21)*'Resumen Cuadrillas'!H5)+(('Resumen Cuadrillas'!C6<=21)*('Resumen Cuadrillas'!D6>=21)*'Resumen Cuadrillas'!H6)+(('Resumen Cuadrillas'!C7<=21)*('Resumen Cuadrillas'!D7>=21)*'Resumen Cuadrillas'!H7)+(('Resumen Cuadrillas'!C8<=21)*('Resumen Cuadrillas'!D8>=21)*'Resumen Cuadrillas'!H8)+(('Resumen Cuadrillas'!C9<=21)*('Resumen Cuadrillas'!D9>=21)*'Resumen Cuadrillas'!H9)+(('Resumen Cuadrillas'!C10<=21)*('Resumen Cuadrillas'!D10>=21)*'Resumen Cuadrillas'!H10)+(('Resumen Cuadrillas'!C11<=21)*('Resumen Cuadrillas'!D11>=21)*'Resumen Cuadrillas'!H11)+(('Resumen Cuadrillas'!C12<=21)*('Resumen Cuadrillas'!D12>=21)*'Resumen Cuadrillas'!H12)+(('Resumen Cuadrillas'!C13<=21)*('Resumen Cuadrillas'!D13>=21)*'Resumen Cuadrillas'!H13)+(('Resumen Cuadrillas'!C14<=21)*('Resumen Cuadrillas'!D14>=21)*'Resumen Cuadrillas'!H14)+(('Resumen Cuadrillas'!C15<=21)*('Resumen Cuadrillas'!D15>=21)*'Resumen Cuadrillas'!H15)+(('Resumen Cuadrillas'!C16<=21)*('Resumen Cuadrillas'!D16>=21)*'Resumen Cuadrillas'!H16)+(('Resumen Cuadrillas'!C17<=21)*('Resumen Cuadrillas'!D17>=21)*'Resumen Cuadrillas'!H17) -> 24
A25: 22 | B25: =(('Resumen Cuadrillas'!C4<=22)*('Resumen Cuadrillas'!D4>=22)*'Resumen Cuadrillas'!H4)+(('Resumen Cuadrillas'!C5<=22)*('Resumen Cuadrillas'!D5>=22)*'Resumen Cuadrillas'!H5)+(('Resumen Cuadrillas'!C6<=22)*('Resumen Cuadrillas'!D6>=22)*'Resumen Cuadrillas'!H6)+(('Resumen Cuadrillas'!C7<=22)*('Resumen Cuadrillas'!D7>=22)*'Resumen Cuadrillas'!H7)+(('Resumen Cuadrillas'!C8<=22)*('Resumen Cuadrillas'!D8>=22)*'Resumen Cuadrillas'!H8)+(('Resumen Cuadrillas'!C9<=22)*('Resumen Cuadrillas'!D9>=22)*'Resumen Cuadrillas'!H9)+(('Resumen Cuadrillas'!C10<=22)*('Resumen Cuadrillas'!D10>=22)*'Resumen Cuadrillas'!H10)+(('Resumen Cuadrillas'!C11<=22)*('Resumen Cuadrillas'!D11>=22)*'Resumen Cuadrillas'!H11)+(('Resumen Cuadrillas'!C12<=22)*('Resumen Cuadrillas'!D12>=22)*'Resumen Cuadrillas'!H12)+(('Resumen Cuadrillas'!C13<=22)*('Resumen Cuadrillas'!D13>=22)*'Resumen Cuadrillas'!H13)+(('Resumen Cuadrillas'!C14<=22)*('Resumen Cuadrillas'!D14>=22)*'Resumen Cuadrillas'!H14)+(('Resumen Cuadrillas'!C15<=22)*('Resumen Cuadrillas'!D15>=22)*'Resumen Cuadrillas'!H15)+(('Resumen Cuadrillas'!C16<=22)*('Resumen Cuadrillas'!D16>=22)*'Resumen Cuadrillas'!H16)+(('Resumen Cuadrillas'!C17<=22)*('Resumen Cuadrillas'!D17>=22)*'Resumen Cuadrillas'!H17) -> 24
A26: 23 | B26: =(('Resumen Cuadrillas'!C4<=23)*('Resumen Cuadrillas'!D4>=23)*'Resumen Cuadrillas'!H4)+(('Resumen Cuadrillas'!C5<=23)*('Resumen Cuadrillas'!D5>=23)*'Resumen Cuadrillas'!H5)+(('Resumen Cuadrillas'!C6<=23)*('Resumen Cuadrillas'!D6>=23)*'Resumen Cuadrillas'!H6)+(('Resumen Cuadrillas'!C7<=23)*('Resumen Cuadrillas'!D7>=23)*'Resumen Cuadrillas'!H7)+(('Resumen Cuadrillas'!C8<=23)*('Resumen Cuadrillas'!D8>=23)*'Resumen Cuadrillas'!H8)+(('Resumen Cuadrillas'!C9<=23)*('Resumen Cuadrillas'!D9>=23)*'Resumen Cuadrillas'!H9)+(('Resumen Cuadrillas'!C10<=23)*('Resumen Cuadrillas'!D10>=23)*'Resumen Cuadrillas'!H10)+(('Resumen Cuadrillas'!C11<=23)*('Resumen Cuadrillas'!D11>=23)*'Resumen Cuadrillas'!H11)+(('Resumen Cuadrillas'!C12<=23)*('Resumen Cuadrillas'!D12>=23)*'Resumen Cuadrillas'!H12)+(('Resumen Cuadrillas'!C13<=23)*('Resumen Cuadrillas'!D13>=23)*'Resumen Cuadrillas'!H13)+(('Resumen Cuadrillas'!C14<=23)*('Resumen Cuadrillas'!D14>=23)*'Resumen Cuadrillas'!H14)+(('Resumen Cuadrillas'!C15<=23)*('Resumen Cuadrillas'!D15>=23)*'Resumen Cuadrillas'!H15)+(('Resumen Cuadrillas'!C16<=23)*('Resumen Cuadrillas'!D16>=23)*'Resumen Cuadrillas'!H16)+(('Resumen Cuadrillas'!C17<=23)*('Resumen Cuadrillas'!D17>=23)*'Resumen Cuadrillas'!H17) -> 21
A27: 24 | B27: =(('Resumen Cuadrillas'!C4<=24)*('Resumen Cuadrillas'!D4>=24)*'Resumen Cuadrillas'!H4)+(('Resumen Cuadrillas'!C5<=24)*('Resumen Cuadrillas'!D5>=24)*'Resumen Cuadrillas'!H5)+(('Resumen Cuadrillas'!C6<=24)*('Resumen Cuadrillas'!D6>=24)*'Resumen Cuadrillas'!H6)+(('Resumen Cuadrillas'!C7<=24)*('Resumen Cuadrillas'!D7>=24)*'Resumen Cuadrillas'!H7)+(('Resumen Cuadrillas'!C8<=24)*('Resumen Cuadrillas'!D8>=24)*'Resumen Cuadrillas'!H8)+(('Resumen Cuadrillas'!C9<=24)*('Resumen Cuadrillas'!D9>=24)*'Resumen Cuadrillas'!H9)+(('Resumen Cuadrillas'!C10<=24)*('Resumen Cuadrillas'!D10>=24)*'Resumen Cuadrillas'!H10)+(('Resumen Cuadrillas'!C11<=24)*('Resumen Cuadrillas'!D11>=24)*'Resumen Cuadrillas'!H11)+(('Resumen Cuadrillas'!C12<=24)*('Resumen Cuadrillas'!D12>=24)*'Resumen Cuadrillas'!H12)+(('Resumen Cuadrillas'!C13<=24)*('Resumen Cuadrillas'!D13>=24)*'Resumen Cuadrillas'!H13)+(('Resumen Cuadrillas'!C14<=24)*('Resumen Cuadrillas'!D14>=24)*'Resumen Cuadrillas'!H14)+(('Resumen Cuadrillas'!C15<=24)*('Resumen Cuadrillas'!D15>=24)*'Resumen Cuadrillas'!H15)+(('Resumen Cuadrillas'!C16<=24)*('Resumen Cuadrillas'!D16>=24)*'Resumen Cuadrillas'!H16)+(('Resumen Cuadrillas'!C17<=24)*('Resumen Cuadrillas'!D17>=24)*'Resumen Cuadrillas'!H17) -> 21
A28: 25 | B28: =(('Resumen Cuadrillas'!C4<=25)*('Resumen Cuadrillas'!D4>=25)*'Resumen Cuadrillas'!H4)+(('Resumen Cuadrillas'!C5<=25)*('Resumen Cuadrillas'!D5>=25)*'Resumen Cuadrillas'!H5)+(('Resumen Cuadrillas'!C6<=25)*('Resumen Cuadrillas'!D6>=25)*'Resumen Cuadrillas'!H6)+(('Resumen Cuadrillas'!C7<=25)*('Resumen Cuadrillas'!D7>=25)*'Resumen Cuadrillas'!H7)+(('Resumen Cuadrillas'!C8<=25)*('Resumen Cuadrillas'!D8>=25)*'Resumen Cuadrillas'!H8)+(('Resumen Cuadrillas'!C9<=25)*('Resumen Cuadrillas'!D9>=25)*'Resumen Cuadrillas'!H9)+(('Resumen Cuadrillas'!C10<=25)*('Resumen Cuadrillas'!D10>=25)*'Resumen Cuadrillas'!H10)+(('Resumen Cuadrillas'!C11<=25)*('Resumen Cuadrillas'!D11>=25)*'Resumen Cuadrillas'!H11)+(('Resumen Cuadrillas'!C12<=25)*('Resumen Cuadrillas'!D12>=25)*'Resumen Cuadrillas'!H12)+(('Resumen Cuadrillas'!C13<=25)*('Resumen Cuadrillas'!D13>=25)*'Resumen Cuadrillas'!H13)+(('Resumen Cuadrillas'!C14<=25)*('Resumen Cuadrillas'!D14>=25)*'Resumen Cuadrillas'!H14)+(('Resumen Cuadrillas'!C15<=25)*('Resumen Cuadrillas'!D15>=25)*'Resumen Cuadrillas'!H15)+(('Resumen Cuadrillas'!C16<=25)*('Resumen Cuadrillas'!D16>=25)*'Resumen Cuadrillas'!H16)+(('Resumen Cuadrillas'!C17<=25)*('Resumen Cuadrillas'!D17>=25)*'Resumen Cuadrillas'!H17) -> 21
A29: 26 | B29: =(('Resumen Cuadrillas'!C4<=26)*('Resumen Cuadrillas'!D4>=26)*'Resumen Cuadrillas'!H4)+(('Resumen Cuadrillas'!C5<=26)*('Resumen Cuadrillas'!D5>=26)*'Resumen Cuadrillas'!H5)+(('Resumen Cuadrillas'!C6<=26)*('Resumen Cuadrillas'!D6>=26)*'Resumen Cuadrillas'!H6)+(('Resumen Cuadrillas'!C7<=26)*('Resumen Cuadrillas'!D7>=26)*'Resumen Cuadrillas'!H7)+(('Resumen Cuadrillas'!C8<=26)*('Resumen Cuadrillas'!D8>=26)*'Resumen Cuadrillas'!H8)+(('Resumen Cuadrillas'!C9<=26)*('Resumen Cuadrillas'!D9>=26)*'Resumen Cuadrillas'!H9)+(('Resumen Cuadrillas'!C10<=26)*('Resumen Cuadrillas'!D10>=26)*'Resumen Cuadrillas'!H10)+(('Resumen Cuadrillas'!C11<=26)*('Resumen Cuadrillas'!D11>=26)*'Resumen Cuadrillas'!H11)+(('Resumen Cuadrillas'!C12<=26)*('Resumen Cuadrillas'!D12>=26)*'Resumen Cuadrillas'!H12)+(('Resumen Cuadrillas'!C13<=26)*('Resumen Cuadrillas'!D13>=26)*'Resumen Cuadrillas'!H13)+(('Resumen Cuadrillas'!C14<=26)*('Resumen Cuadrillas'!D14>=26)*'Resumen Cuadrillas'!H14)+(('Resumen Cuadrillas'!C15<=26)*('Resumen Cuadrillas'!D15>=26)*'Resumen Cuadrillas'!H15)+(('Resumen Cuadrillas'!C16<=26)*('Resumen Cuadrillas'!D16>=26)*'Resumen Cuadrillas'!H16)+(('Resumen Cuadrillas'!C17<=26)*('Resumen Cuadrillas'!D17>=26)*'Resumen Cuadrillas'!H17) -> 25
A30: 27 | B30: =(('Resumen Cuadrillas'!C4<=27)*('Resumen Cuadrillas'!D4>=27)*'Resumen Cuadrillas'!H4)+(('Resumen Cuadrillas'!C5<=27)*('Resumen Cuadrillas'!D5>=27)*'Resumen Cuadrillas'!H5)+(('Resumen Cuadrillas'!C6<=27)*('Resumen Cuadrillas'!D6>=27)*'Resumen Cuadrillas'!H6)+(('Resumen Cuadrillas'!C7<=27)*('Resumen Cuadrillas'!D7>=27)*'Resumen Cuadrillas'!H7)+(('Resumen Cuadrillas'!C8<=27)*('Resumen Cuadrillas'!D8>=27)*'Resumen Cuadrillas'!H8)+(('Resumen Cuadrillas'!C9<=27)*('Resumen Cuadrillas'!D9>=27)*'Resumen Cuadrillas'!H9)+(('Resumen Cuadrillas'!C10<=27)*('Resumen Cuadrillas'!D10>=27)*'Resumen Cuadrillas'!H10)+(('Resumen Cuadrillas'!C11<=27)*('Resumen Cuadrillas'!D11>=27)*'Resumen Cuadrillas'!H11)+(('Resumen Cuadrillas'!C12<=27)*('Resumen Cuadrillas'!D12>=27)*'Resumen Cuadrillas'!H12)+(('Resumen Cuadrillas'!C13<=27)*('Resumen Cuadrillas'!D13>=27)*'Resumen Cuadrillas'!H13)+(('Resumen Cuadrillas'!C14<=27)*('Resumen Cuadrillas'!D14>=27)*'Resumen Cuadrillas'!H14)+(('Resumen Cuadrillas'!C15<=27)*('Resumen Cuadrillas'!D15>=27)*'Resumen Cuadrillas'!H15)+(('Resumen Cuadrillas'!C16<=27)*('Resumen Cuadrillas'!D16>=27)*'Resumen Cuadrillas'!H16)+(('Resumen Cuadrillas'!C17<=27)*('Resumen Cuadrillas'!D17>=27)*'Resumen Cuadrillas'!H17) -> 19
A31: 28 | B31: =(('Resumen Cuadrillas'!C4<=28)*('Resumen Cuadrillas'!D4>=28)*'Resumen Cuadrillas'!H4)+(('Resumen Cuadrillas'!C5<=28)*('Resumen Cuadrillas'!D5>=28)*'Resumen Cuadrillas'!H5)+(('Resumen Cuadrillas'!C6<=28)*('Resumen Cuadrillas'!D6>=28)*'Resumen Cuadrillas'!H6)+(('Resumen Cuadrillas'!C7<=28)*('Resumen Cuadrillas'!D7>=28)*'Resumen Cuadrillas'!H7)+(('Resumen Cuadrillas'!C8<=28)*('Resumen Cuadrillas'!D8>=28)*'Resumen Cuadrillas'!H8)+(('Resumen Cuadrillas'!C9<=28)*('Resumen Cuadrillas'!D9>=28)*'Resumen Cuadrillas'!H9)+(('Resumen Cuadrillas'!C10<=28)*('Resumen Cuadrillas'!D10>=28)*'Resumen Cuadrillas'!H10)+(('Resumen Cuadrillas'!C11<=28)*('Resumen Cuadrillas'!D11>=28)*'Resumen Cuadrillas'!H11)+(('Resumen Cuadrillas'!C12<=28)*('Resumen Cuadrillas'!D12>=28)*'Resumen Cuadrillas'!H12)+(('Resumen Cuadrillas'!C13<=28)*('Resumen Cuadrillas'!D13>=28)*'Resumen Cuadrillas'!H13)+(('Resumen Cuadrillas'!C14<=28)*('Resumen Cuadrillas'!D14>=28)*'Resumen Cuadrillas'!H14)+(('Resumen Cuadrillas'!C15<=28)*('Resumen Cuadrillas'!D15>=28)*'Resumen Cuadrillas'!H15)+(('Resumen Cuadrillas'!C16<=28)*('Resumen Cuadrillas'!D16>=28)*'Resumen Cuadrillas'!H16)+(('Resumen Cuadrillas'!C17<=28)*('Resumen Cuadrillas'!D17>=28)*'Resumen Cuadrillas'!H17) -> 19
A32: 29 | B32: =(('Resumen Cuadrillas'!C4<=29)*('Resumen Cuadrillas'!D4>=29)*'Resumen Cuadrillas'!H4)+(('Resumen Cuadrillas'!C5<=29)*('Resumen Cuadrillas'!D5>=29)*'Resumen Cuadrillas'!H5)+(('Resumen Cuadrillas'!C6<=29)*('Resumen Cuadrillas'!D6>=29)*'Resumen Cuadrillas'!H6)+(('Resumen Cuadrillas'!C7<=29)*('Resumen Cuadrillas'!D7>=29)*'Resumen Cuadrillas'!H7)+(('Resumen Cuadrillas'!C8<=29)*('Resumen Cuadrillas'!D8>=29)*'Resumen Cuadrillas'!H8)+(('Resumen Cuadrillas'!C9<=29)*('Resumen Cuadrillas'!D9>=29)*'Resumen Cuadrillas'!H9)+(('Resumen Cuadrillas'!C10<=29)*('Resumen Cuadrillas'!D10>=29)*'Resumen Cuadrillas'!H10)+(('Resumen Cuadrillas'!C11<=29)*('Resumen Cuadrillas'!D11>=29)*'Resumen Cuadrillas'!H11)+(('Resumen Cuadrillas'!C12<=29)*('Resumen Cuadrillas'!D12>=29)*'Resumen Cuadrillas'!H12)+(('Resumen Cuadrillas'!C13<=29)*('Resumen Cuadrillas'!D13>=29)*'Resumen Cuadrillas'!H13)+(('Resumen Cuadrillas'!C14<=29)*('Resumen Cuadrillas'!D14>=29)*'Resumen Cuadrillas'!H14)+(('Resumen Cuadrillas'!C15<=29)*('Resumen Cuadrillas'!D15>=29)*'Resumen Cuadrillas'!H15)+(('Resumen Cuadrillas'!C16<=29)*('Resumen Cuadrillas'!D16>=29)*'Resumen Cuadrillas'!H16)+(('Resumen Cuadrillas'!C17<=29)*('Resumen Cuadrillas'!D17>=29)*'Resumen Cuadrillas'!H17) -> 17
A33: 30 | B33: =(('Resumen Cuadrillas'!C4<=30)*('Resumen Cuadrillas'!D4>=30)*'Resumen Cuadrillas'!H4)+(('Resumen Cuadrillas'!C5<=30)*('Resumen Cuadrillas'!D5>=30)*'Resumen Cuadrillas'!H5)+(('Resumen Cuadrillas'!C6<=30)*('Resumen Cuadrillas'!D6>=30)*'Resumen Cuadrillas'!H6)+(('Resumen Cuadrillas'!C7<=30)*('Resumen Cuadrillas'!D7>=30)*'Resumen Cuadrillas'!H7)+(('Resumen Cuadrillas'!C8<=30)*('Resumen Cuadrillas'!D8>=30)*'Resumen Cuadrillas'!H8)+(('Resumen Cuadrillas'!C9<=30)*('Resumen Cuadrillas'!D9>=30)*'Resumen Cuadrillas'!H9)+(('Resumen Cuadrillas'!C10<=30)*('Resumen Cuadrillas'!D10>=30)*'Resumen Cuadrillas'!H10)+(('Resumen Cuadrillas'!C11<=30)*('Resumen Cuadrillas'!D11>=30)*'Resumen Cuadrillas'!H11)+(('Resumen Cuadrillas'!C12<=30)*('Resumen Cuadrillas'!D12>=30)*'Resumen Cuadrillas'!H12)+(('Resumen Cuadrillas'!C13<=30)*('Resumen Cuadrillas'!D13>=30)*'Resumen Cuadrillas'!H13)+(('Resumen Cuadrillas'!C14<=30)*('Resumen Cuadrillas'!D14>=30)*'Resumen Cuadrillas'!H14)+(('Resumen Cuadrillas'!C15<=30)*('Resumen Cuadrillas'!D15>=30)*'Resumen Cuadrillas'!H15)+(('Resumen Cuadrillas'!C16<=30)*('Resumen Cuadrillas'!D16>=30)*'Resumen Cuadrillas'!H16)+(('Resumen Cuadrillas'!C17<=30)*('Resumen Cuadrillas'!D17>=30)*'Resumen Cuadrillas'!H17) -> 17
A34: 31 | B34: =(('Resumen Cuadrillas'!C4<=31)*('Resumen Cuadrillas'!D4>=31)*'Resumen Cuadrillas'!H4)+(('Resumen Cuadrillas'!C5<=31)*('Resumen Cuadrillas'!D5>=31)*'Resumen Cuadrillas'!H5)+(('Resumen Cuadrillas'!C6<=31)*('Resumen Cuadrillas'!D6>=31)*'Resumen Cuadrillas'!H6)+(('Resumen Cuadrillas'!C7<=31)*('Resumen Cuadrillas'!D7>=31)*'Resumen Cuadrillas'!H7)+(('Resumen Cuadrillas'!C8<=31)*('Resumen Cuadrillas'!D8>=31)*'Resumen Cuadrillas'!H8)+(('Resumen Cuadrillas'!C9<=31)*('Resumen Cuadrillas'!D9>=31)*'Resumen Cuadrillas'!H9)+(('Resumen Cuadrillas'!C10<=31)*('Resumen Cuadrillas'!D10>=31)*'Resumen Cuadrillas'!H10)+(('Resumen Cuadrillas'!C11<=31)*('Resumen Cuadrillas'!D11>=31)*'Resumen Cuadrillas'!H11)+(('Resumen Cuadrillas'!C12<=31)*('Resumen Cuadrillas'!D12>=31)*'Resumen Cuadrillas'!H12)+(('Resumen Cuadrillas'!C13<=31)*('Resumen Cuadrillas'!D13>=31)*'Resumen Cuadrillas'!H13)+(('Resumen Cuadrillas'!C14<=31)*('Resumen Cuadrillas'!D14>=31)*'Resumen Cuadrillas'!H14)+(('Resumen Cuadrillas'!C15<=31)*('Resumen Cuadrillas'!D15>=31)*'Resumen Cuadrillas'!H15)+(('Resumen Cuadrillas'!C16<=31)*('Resumen Cuadrillas'!D16>=31)*'Resumen Cuadrillas'!H16)+(('Resumen Cuadrillas'!C17<=31)*('Resumen Cuadrillas'!D17>=31)*'Resumen Cuadrillas'!H17) -> 9
A35: 32 | B35: =(('Resumen Cuadrillas'!C4<=32)*('Resumen Cuadrillas'!D4>=32)*'Resumen Cuadrillas'!H4)+(('Resumen Cuadrillas'!C5<=32)*('Resumen Cuadrillas'!D5>=32)*'Resumen Cuadrillas'!H5)+(('Resumen Cuadrillas'!C6<=32)*('Resumen Cuadrillas'!D6>=32)*'Resumen Cuadrillas'!H6)+(('Resumen Cuadrillas'!C7<=32)*('Resumen Cuadrillas'!D7>=32)*'Resumen Cuadrillas'!H7)+(('Resumen Cuadrillas'!C8<=32)*('Resumen Cuadrillas'!D8>=32)*'Resumen Cuadrillas'!H8)+(('Resumen Cuadrillas'!C9<=32)*('Resumen Cuadrillas'!D9>=32)*'Resumen Cuadrillas'!H9)+(('Resumen Cuadrillas'!C10<=32)*('Resumen Cuadrillas'!D10>=32)*'Resumen Cuadrillas'!H10)+(('Resumen Cuadrillas'!C11<=32)*('Resumen Cuadrillas'!D11>=32)*'Resumen Cuadrillas'!H11)+(('Resumen Cuadrillas'!C12<=32)*('Resumen Cuadrillas'!D12>=32)*'Resumen Cuadrillas'!H12)+(('Resumen Cuadrillas'!C13<=32)*('Resumen Cuadrillas'!D13>=32)*'Resumen Cuadrillas'!H13)+(('Resumen Cuadrillas'!C14<=32)*('Resumen Cuadrillas'!D14>=32)*'Resumen Cuadrillas'!H14)+(('Resumen Cuadrillas'!C15<=32)*('Resumen Cuadrillas'!D15>=32)*'Resumen Cuadrillas'!H15)+(('Resumen Cuadrillas'!C16<=32)*('Resumen Cuadrillas'!D16>=32)*'Resumen Cuadrillas'!H16)+(('Resumen Cuadrillas'!C17<=32)*('Resumen Cuadrillas'!D17>=32)*'Resumen Cuadrillas'!H17) -> 9
A36: 33 | B36: =(('Resumen Cuadrillas'!C4<=33)*('Resumen Cuadrillas'!D4>=33)*'Resumen Cuadrillas'!H4)+(('Resumen Cuadrillas'!C5<=33)*('Resumen Cuadrillas'!D5>=33)*'Resumen Cuadrillas'!H5)+(('Resumen Cuadrillas'!C6<=33)*('Resumen Cuadrillas'!D6>=33)*'Resumen Cuadrillas'!H6)+(('Resumen Cuadrillas'!C7<=33)*('Resumen Cuadrillas'!D7>=33)*'Resumen Cuadrillas'!H7)+(('Resumen Cuadrillas'!C8<=33)*('Resumen Cuadrillas'!D8>=33)*'Resumen Cuadrillas'!H8)+(('Resumen Cuadrillas'!C9<=33)*('Resumen Cuadrillas'!D9>=33)*'Resumen Cuadrillas'!H9)+(('Resumen Cuadrillas'!C10<=33)*('Resumen Cuadrillas'!D10>=33)*'Resumen Cuadrillas'!H10)+(('Resumen Cuadrillas'!C11<=33)*('Resumen Cuadrillas'!D11>=33)*'Resumen Cuadrillas'!H11)+(('Resumen Cuadrillas'!C12<=33)*('Resumen Cuadrillas'!D12>=33)*'Resumen Cuadrillas'!H12)+(('Resumen Cuadrillas'!C13<=33)*('Resumen Cuadrillas'!D13>=33)*'Resumen Cuadrillas'!H13)+(('Resumen Cuadrillas'!C14<=33)*('Resumen Cuadrillas'!D14>=33)*'Resumen Cuadrillas'!H14)+(('Resumen Cuadrillas'!C15<=33)*('Resumen Cuadrillas'!D15>=33)*'Resumen Cuadrillas'!H15)+(('Resumen Cuadrillas'!C16<=33)*('Resumen Cuadrillas'!D16>=33)*'Resumen Cuadrillas'!H16)+(('Resumen Cuadrillas'!C17<=33)*('Resumen Cuadrillas'!D17>=33)*'Resumen Cuadrillas'!H17) -> 9
A37: 34 | B37: =(('Resumen Cuadrillas'!C4<=34)*('Resumen Cuadrillas'!D4>=34)*'Resumen Cuadrillas'!H4)+(('Resumen Cuadrillas'!C5<=34)*('Resumen Cuadrillas'!D5>=34)*'Resumen Cuadrillas'!H5)+(('Resumen Cuadrillas'!C6<=34)*('Resumen Cuadrillas'!D6>=34)*'Resumen Cuadrillas'!H6)+(('Resumen Cuadrillas'!C7<=34)*('Resumen Cuadrillas'!D7>=34)*'Resumen Cuadrillas'!H7)+(('Resumen Cuadrillas'!C8<=34)*('Resumen Cuadrillas'!D8>=34)*'Resumen Cuadrillas'!H8)+(('Resumen Cuadrillas'!C9<=34)*('Resumen Cuadrillas'!D9>=34)*'Resumen Cuadrillas'!H9)+(('Resumen Cuadrillas'!C10<=34)*('Resumen Cuadrillas'!D10>=34)*'Resumen Cuadrillas'!H10)+(('Resumen Cuadrillas'!C11<=34)*('Resumen Cuadrillas'!D11>=34)*'Resumen Cuadrillas'!H11)+(('Resumen Cuadrillas'!C12<=34)*('Resumen Cuadrillas'!D12>=34)*'Resumen Cuadrillas'!H12)+(('Resumen Cuadrillas'!C13<=34)*('Resumen Cuadrillas'!D13>=34)*'Resumen Cuadrillas'!H13)+(('Resumen Cuadrillas'!C14<=34)*('Resumen Cuadrillas'!D14>=34)*'Resumen Cuadrillas'!H14)+(('Resumen Cuadrillas'!C15<=34)*('Resumen Cuadrillas'!D15>=34)*'Resumen Cuadrillas'!H15)+(('Resumen Cuadrillas'!C16<=34)*('Resumen Cuadrillas'!D16>=34)*'Resumen Cuadrillas'!H16)+(('Resumen Cuadrillas'!C17<=34)*('Resumen Cuadrillas'!D17>=34)*'Resumen Cuadrillas'!H17) -> 11
A38: 35 | B38: =(('Resumen Cuadrillas'!C4<=35)*('Resumen Cuadrillas'!D4>=35)*'Resumen Cuadrillas'!H4)+(('Resumen Cuadrillas'!C5<=35)*('Resumen Cuadrillas'!D5>=35)*'Resumen Cuadrillas'!H5)+(('Resumen Cuadrillas'!C6<=35)*('Resumen Cuadrillas'!D6>=35)*'Resumen Cuadrillas'!H6)+(('Resumen Cuadrillas'!C7<=35)*('Resumen Cuadrillas'!D7>=35)*'Resumen Cuadrillas'!H7)+(('Resumen Cuadrillas'!C8<=35)*('Resumen Cuadrillas'!D8>=35)*'Resumen Cuadrillas'!H8)+(('Resumen Cuadrillas'!C9<=35)*('Resumen Cuadrillas'!D9>=35)*'Resumen Cuadrillas'!H9)+(('Resumen Cuadrillas'!C10<=35)*('Resumen Cuadrillas'!D10>=35)*'Resumen Cuadrillas'!H10)+(('Resumen Cuadrillas'!C11<=35)*('Resumen Cuadrillas'!D11>=35)*'Resumen Cuadrillas'!H11)+(('Resumen Cuadrillas'!C12<=35)*('Resumen Cuadrillas'!D12>=35)*'Resumen Cuadrillas'!H12)+(('Resumen Cuadrillas'!C13<=35)*('Resumen Cuadrillas'!D13>=35)*'Resumen Cuadrillas'!H13)+(('Resumen Cuadrillas'!C14<=35)*('Resumen Cuadrillas'!D14>=35)*'Resumen Cuadrillas'!H14)+(('Resumen Cuadrillas'!C15<=35)*('Resumen Cuadrillas'!D15>=35)*'Resumen Cuadrillas'!H15)+(('Resumen Cuadrillas'!C16<=35)*('Resumen Cuadrillas'!D16>=35)*'Resumen Cuadrillas'!H16)+(('Resumen Cuadrillas'!C17<=35)*('Resumen Cuadrillas'!D17>=35)*'Resumen Cuadrillas'!H17) -> 7
A39: 36 | B39: =(('Resumen Cuadrillas'!C4<=36)*('Resumen Cuadrillas'!D4>=36)*'Resumen Cuadrillas'!H4)+(('Resumen Cuadrillas'!C5<=36)*('Resumen Cuadrillas'!D5>=36)*'Resumen Cuadrillas'!H5)+(('Resumen Cuadrillas'!C6<=36)*('Resumen Cuadrillas'!D6>=36)*'Resumen Cuadrillas'!H6)+(('Resumen Cuadrillas'!C7<=36)*('Resumen Cuadrillas'!D7>=36)*'Resumen Cuadrillas'!H7)+(('Resumen Cuadrillas'!C8<=36)*('Resumen Cuadrillas'!D8>=36)*'Resumen Cuadrillas'!H8)+(('Resumen Cuadrillas'!C9<=36)*('Resumen Cuadrillas'!D9>=36)*'Resumen Cuadrillas'!H9)+(('Resumen Cuadrillas'!C10<=36)*('Resumen Cuadrillas'!D10>=36)*'Resumen Cuadrillas'!H10)+(('Resumen Cuadrillas'!C11<=36)*('Resumen Cuadrillas'!D11>=36)*'Resumen Cuadrillas'!H11)+(('Resumen Cuadrillas'!C12<=36)*('Resumen Cuadrillas'!D12>=36)*'Resumen Cuadrillas'!H12)+(('Resumen Cuadrillas'!C13<=36)*('Resumen Cuadrillas'!D13>=36)*'Resumen Cuadrillas'!H13)+(('Resumen Cuadrillas'!C14<=36)*('Resumen Cuadrillas'!D14>=36)*'Resumen Cuadrillas'!H14)+(('Resumen Cuadrillas'!C15<=36)*('Resumen Cuadrillas'!D15>=36)*'Resumen Cuadrillas'!H15)+(('Resumen Cuadrillas'!C16<=36)*('Resumen Cuadrillas'!D16>=36)*'Resumen Cuadrillas'!H16)+(('Resumen Cuadrillas'!C17<=36)*('Resumen Cuadrillas'!D17>=36)*'Resumen Cuadrillas'!H17) -> 7
A40: 37 | B40: =(('Resumen Cuadrillas'!C4<=37)*('Resumen Cuadrillas'!D4>=37)*'Resumen Cuadrillas'!H4)+(('Resumen Cuadrillas'!C5<=37)*('Resumen Cuadrillas'!D5>=37)*'Resumen Cuadrillas'!H5)+(('Resumen Cuadrillas'!C6<=37)*('Resumen Cuadrillas'!D6>=37)*'Resumen Cuadrillas'!H6)+(('Resumen Cuadrillas'!C7<=37)*('Resumen Cuadrillas'!D7>=37)*'Resumen Cuadrillas'!H7)+(('Resumen Cuadrillas'!C8<=37)*('Resumen Cuadrillas'!D8>=37)*'Resumen Cuadrillas'!H8)+(('Resumen Cuadrillas'!C9<=37)*('Resumen Cuadrillas'!D9>=37)*'Resumen Cuadrillas'!H9)+(('Resumen Cuadrillas'!C10<=37)*('Resumen Cuadrillas'!D10>=37)*'Resumen Cuadrillas'!H10)+(('Resumen Cuadrillas'!C11<=37)*('Resumen Cuadrillas'!D11>=37)*'Resumen Cuadrillas'!H11)+(('Resumen Cuadrillas'!C12<=37)*('Resumen Cuadrillas'!D12>=37)*'Resumen Cuadrillas'!H12)+(('Resumen Cuadrillas'!C13<=37)*('Resumen Cuadrillas'!D13>=37)*'Resumen Cuadrillas'!H13)+(('Resumen Cuadrillas'!C14<=37)*('Resumen Cuadrillas'!D14>=37)*'Resumen Cuadrillas'!H14)+(('Resumen Cuadrillas'!C15<=37)*('Resumen Cuadrillas'!D15>=37)*'Resumen Cuadrillas'!H15)+(('Resumen Cuadrillas'!C16<=37)*('Resumen Cuadrillas'!D16>=37)*'Resumen Cuadrillas'!H16)+(('Resumen Cuadrillas'!C17<=37)*('Resumen Cuadrillas'!D17>=37)*'Resumen Cuadrillas'!H17) -> 7
A41: 38 | B41: =(('Resumen Cuadrillas'!C4<=38)*('Resumen Cuadrillas'!D4>=38)*'Resumen Cuadrillas'!H4)+(('Resumen Cuadrillas'!C5<=38)*('Resumen Cuadrillas'!D5>=38)*'Resumen Cuadrillas'!H5)+(('Resumen Cuadrillas'!C6<=38)*('Resumen Cuadrillas'!D6>=38)*'Resumen Cuadrillas'!H6)+(('Resumen Cuadrillas'!C7<=38)*('Resumen Cuadrillas'!D7>=38)*'Resumen Cuadrillas'!H7)+(('Resumen Cuadrillas'!C8<=38)*('Resumen Cuadrillas'!D8>=38)*'Resumen Cuadrillas'!H8)+(('Resumen Cuadrillas'!C9<=38)*('Resumen Cuadrillas'!D9>=38)*'Resumen Cuadrillas'!H9)+(('Resumen Cuadrillas'!C10<=38)*('Resumen Cuadrillas'!D10>=38)*'Resumen Cuadrillas'!H10)+(('Resumen Cuadrillas'!C11<=38)*('Resumen Cuadrillas'!D11>=38)*'Resumen Cuadrillas'!H11)+(('Resumen Cuadrillas'!C12<=38)*('Resumen Cuadrillas'!D12>=38)*'Resumen Cuadrillas'!H12)+(('Resumen Cuadrillas'!C13<=38)*('Resumen Cuadrillas'!D13>=38)*'Resumen Cuadrillas'!H13)+(('Resumen Cuadrillas'!C14<=38)*('Resumen Cuadrillas'!D14>=38)*'Resumen Cuadrillas'!H14)+(('Resumen Cuadrillas'!C15<=38)*('Resumen Cuadrillas'!D15>=38)*'Resumen Cuadrillas'!H15)+(('Resumen Cuadrillas'!C16<=38)*('Resumen Cuadrillas'!D16>=38)*'Resumen Cuadrillas'!H16)+(('Resumen Cuadrillas'!C17<=38)*('Resumen Cuadrillas'!D17>=38)*'Resumen Cuadrillas'!H17) -> 15
...

Sheet Chequeo vs Presupuesto
A1: CHEQUEO: ¿LA DOTACIÓN Y MAQUINARIA DEL PROGRAMA CUADRAN CON EL PRESUPUESTO?
A2: Mano de obra de las cuadrillas viene del Subtotal de partidas (precio unitario). Gastos Generales (GG) NO es mano de obra adicional: financia supervisión, maquinaria/equipos, bodega, cierre de faena, seguros, agua/luz.
A4: BLOQUE 1 — MANO DE OBRA (viene del Subtotal de Partidas, NO de los GG)
A5: Subtotal partidas a cotizar (CLP) — de tu presupuesto | B5: 84407369
A6: % estimado de Mano de Obra dentro del precio unitario (ajustable) | B6: 0.4
A7: Mano de obra implícita en las partidas (CLP) | B7: =B5*B6 -> 33762948
A8: Jornal diario promedio por persona, costo empresa c/cargas (CLP) (ajustable) | B8: 35000
A9: Días corridos totales del programa | B9: 60
A10: Días hábiles estimados (60 corridos - domingos) | B10: =B9-ROUND(B9/7,0) -> 51
A11: Personas-día que financian las partidas (Mano de obra / Jornal) | B11: =B7/B8 -> 964.65565
A12: Dotación PROMEDIO que las partidas pueden financiar | B12: =B11/B10 -> 18.914817
A13: Personas-día que efectivamente usa el programa (Carta Gantt) | B13: ='Resumen Cuadrillas'!B19 -> 583
A14: Dotación PROMEDIO del programa (Carta Gantt) | B14: ='Dotación Diaria'!B66 -> 14.416667
A15: Dotación PEAK del programa (Carta Gantt) | B15: ='Dotación Diaria'!B65 -> 28
A16: Holgura mano de obra (personas-día) | B16: =B11-B13 -> 381.65565
A17: ¿Cuadra la mano de obra? | B17: =IF(B11>=B13,"SÍ, hay holgura","NO, excede lo que financian las partidas") -> SÍ, hay holgura
A19: BLOQUE 2 — GASTOS GENERALES (maquinaria, equipos, supervisión, faena)
A20: Gastos Generales del presupuesto (CLP) — 28% del subtotal | B20: 23634063
A21: % GG destinado a Maquinaria y Equipos (ajustable) | B21: 0.35
A22: % GG destinado a Administración / Supervisión (ajustable) | B22: 0.4
A23: % GG destinado a Otros (bodega, cierre, agua/luz, seguros) (ajustable) | B23: 0.25
A24: Monto GG para Maquinaria y Equipos (CLP) | B24: =B20*B21 -> 8271922
A25: Monto GG para Administración/Supervisión (CLP) | B25: =B20*B22 -> 9453625.2
A26: Monto GG para Otros (CLP) | B26: =B20*B23 -> 5908515.8
A28: BLOQUE 3 — MAQUINARIA/EQUIPOS QUE REQUIERE EL PROGRAMA (estimado, contra GG-Maquinaria)
A29: Equipo / Arriendo | B29: Cuadrilla que lo usa | C29: Costo diario arriendo (CLP, ajustable) | D29: Días de uso (según duración real) | E29: Costo total (CLP)
A30: Martillo demoledor + compresor | B30: T1. Demolición y Retiros | C30: 45000 | D30: ='Resumen Cuadrillas'!I4 -> 8 | E30: =C30*D30 -> 360000
A31: Mixer/betonera + vibrador hormigón | B31: T2. Obra Gruesa / Hormigones | C31: 35000 | D31: ='Resumen Cuadrillas'!I5 -> 9 | E31: =C31*D31 -> 315000
A32: Dobladora/cizalla fierro | B32: T3. Enfierradura | C32: 20000 | D32: ='Resumen Cuadrillas'!I6 -> 2 | E32: =C32*D32 -> 40000
A33: Equipo soldadura + amoladora | B33: T6. Estructura Metálica | C33: 30000 | D33: ='Resumen Cuadrillas'!I9 -> 4 | E33: =C33*D33 -> 120000
A34: Andamios + grúa pluma fachada | B34: T11. Hojalatería / Cubierta | C34: 60000 | D34: ='Resumen Cuadrillas'!I15 -> 26 | E34: =C34*D34 -> 1560000
A35: Plataforma elevadora paneles | B35: T7. Paneles Frigoríficos | C35: 50000 | D35: ='Resumen Cuadrillas'!I10 -> 13 | E35: =C35*D35 -> 650000
A36: Herramientas menores varias (todas las cuadrillas) | B36: Todas | C36: 15000 | D36: 60 | E36: =C36*D36 -> 900000
A37: TOTAL maquinaria/equipos requerida por el programa (CLP): | E37: =SUM(E30:E36) -> 3945000
A38: ¿Cuadra la maquinaria contra el monto de GG-Maquinaria? | B38: =IF(B24>=E37,"SÍ, hay holgura","NO, el programa requiere más maquinaria que lo presupuestado en GG") -> SÍ, hay holgura
